Workbook

Sheet Read me
A1: Scoring Calibration Workbook — AI Food Scanner
A3: What this is: a test harness for the v1 scoring formula (docs/SCORING_METHODOLOGY.md). 50 real products across the spectrum, incl. deliberate edge cases that break competitors.
A5: HONEST NOTE ON INPUTS: NOVA group, Nutri-Score, and additive tiers are REPRESENTATIVE values for these well-known products — accurate in kind, not pulled live from Open Food Facts in this session. Before finalising weights, replace with a live OFF/USDA pull (the harness reads the same columns).
A7: How to calibrate: go to the Weights sheet, change the three weights (Processing / Nutrition / Additives). The SCORE and Band columns recompute. Ask: do the RELATIVE rankings feel fair? Mark the 'Feels right?' column y/n and note disagreements.
A9: Watch these edge cases (bold rows on Calibration):
A10: • Sparkling water (high) vs Diet cola (low) — proves processing weighting beats 'diet = healthy'.
A11: • Cheddar cheese vs Froot Loops — the classic Yuka failure; cheese should not lose to sugary cereal.
A12: • Deli ham / bacon — nitrite is higher-concern, but the additive floor(30) stops one additive tanking the score (anti-Yuka).
A13: • Olive oil — whole food with a middling Nutri-Score; check it still lands respectably.
A15: Scale: 0-100, higher = lower-processed/better. Bands: 75-100 Lower-processed (green), 45-74 Moderate (amber), 0-44 Higher-processed (clay). Deliberately non-alarmist — no 'toxic' red.
A17: Next step after calibration: lock the tuned weights back into docs/SCORING_METHODOLOGY.md and, ideally, have a dietitian sanity-check the rankings.

Sheet Weights
A1: SCORING WEIGHTS & MAPPINGS (edit these to calibrate)
A3: Composite weights (must sum to 1.0)
A4: Processing weight | B4: 0.5
A5: Nutrition weight | B5: 0.35
A6: Additives weight | B6: 0.15
A7: SUM (should = 1.0) | B7: =SUM(B4:B6) -> 1
A9: NOVA → processing sub-score
A10: NOVA 1 (unprocessed) | B10: 100
A11: NOVA 2 (culinary ingredient) | B11: 80
A12: NOVA 3 (processed) | B12: 55
A13: NOVA 4 (ultra-processed) | B13: 20
A15: Nutri-Score → nutrition sub-score
A16: Nutri A | B16: 90
A17: Nutri B | B17: 70
A18: Nutri C | B18: 50
A19: Nutri D | B19: 30
A20: Nutri E | B20: 12
A22: Additive penalties (start 100, floor 30)
A23: Low concern | B23: 0 / 0
A24: Moderate | B24: -6 first / -3 each more
A25: Higher concern | B25: -15 first / -8 each more
A26: Floor (min additive sub-score) | B26: 30

Sheet Calibration
A1: # | B1: Product | C1: Category | D1: NOVA | E1: Nutri | F1: Additives | G1: Proc sub | H1: Nutr sub | I1: Add sub | J1: SCORE | K1: Band | L1: Feels right? (y/n) | M1: Notes / edge case
A2: 1 | B2: Extra-virgin olive oil | C2: Oil | D2: 1 | E2: C | F2: 0 | G2: 100 | H2: 50 | I2: 100 | J2: =ROUND(Weights!$B$4*G2+Weights!$B$5*H2+Weights!$B$6*I2,0) -> 83 | K2: =IF(J2>=75,"Lower-processed",IF(J2>=45,"Moderately processed","Higher-processed")) -> Lower-processed | M2: Whole-food fat; Nutri-Score dings fat, processing pristine
A3: 2 | B3: Fresh banana | C3: Fruit | D3: 1 | E3: A | F3: 0 | G3: 100 | H3: 90 | I3: 100 | J3: =ROUND(Weights!$B$4*G3+Weights!$B$5*H3+Weights!$B$6*I3,0) -> 97 | K3: =IF(J3>=75,"Lower-processed",IF(J3>=45,"Moderately processed","Higher-processed")) -> Lower-processed | M3: Baseline whole food
A4: 3 | B4: Raw almonds | C4: Nuts | D4: 1 | E4: A | F4: 0 | G4: 100 | H4: 90 | I4: 100 | J4: =ROUND(Weights!$B$4*G4+Weights!$B$5*H4+Weights!$B$6*I4,0) -> 97 | K4: =IF(J4>=75,"Lower-processed",IF(J4>=45,"Moderately processed","Higher-processed")) -> Lower-processed
A5: 4 | B5: Rolled oats (plain) | C5: Grain | D5: 1 | E5: A | F5: 0 | G5: 100 | H5: 90 | I5: 100 | J5: =ROUND(Weights!$B$4*G5+Weights!$B$5*H5+Weights!$B$6*I5,0) -> 97 | K5: =IF(J5>=75,"Lower-processed",IF(J5>=45,"Moderately processed","Higher-processed")) -> Lower-processed
A6: 5 | B6: White rice | C6: Grain | D6: 1 | E6: A | F6: 0 | G6: 100 | H6: 90 | I6: 100 | J6: =ROUND(Weights!$B$4*G6+Weights!$B$5*H6+Weights!$B$6*I6,0) -> 97 | K6: =IF(J6>=75,"Lower-processed",IF(J6>=45,"Moderately processed","Higher-processed")) -> Lower-processed
A7: 6 | B7: Frozen peas (plain) | C7: Vegetable | D7: 1 | E7: A | F7: 0 | G7: 100 | H7: 90 | I7: 100 | J7: =ROUND(Weights!$B$4*G7+Weights!$B$5*H7+Weights!$B$6*I7,0) -> 97 | K7: =IF(J7>=75,"Lower-processed",IF(J7>=45,"Moderately processed","Higher-processed")) -> Lower-processed
A8: 7 | B8: Whole milk | C8: Dairy | D8: 1 | E8: B | F8: 0 | G8: 100 | H8: 70 | I8: 100 | J8: =ROUND(Weights!$B$4*G8+Weights!$B$5*H8+Weights!$B$6*I8,0) -> 90 | K8: =IF(J8>=75,"Lower-processed",IF(J8>=45,"Moderately processed","Higher-processed")) -> Lower-processed
A9: 8 | B9: Plain Greek yogurt | C9: Dairy | D9: 1 | E9: A | F9: 0 | G9: 100 | H9: 90 | I9: 100 | J9: =ROUND(Weights!$B$4*G9+Weights!$B$5*H9+Weights!$B$6*I9,0) -> 97 | K9: =IF(J9>=75,"Lower-processed",IF(J9>=45,"Moderately processed","Higher-processed")) -> Lower-processed
A10: 9 | B10: Sparkling water (plain) | C10: Beverage | D10: 1 | E10: A | F10: 0 | G10: 100 | H10: 90 | I10: 100 | J10: =ROUND(Weights!$B$4*G10+Weights!$B$5*H10+Weights!$B$6*I10,0) -> 97 | K10: =IF(J10>=75,"Lower-processed",IF(J10>=45,"Moderately processed","Higher-processed")) -> Lower-processed | M10: CONTRAST to diet soda → should score high
A11: 10 | B11: Honey (pure) | C11: Sweetener | D11: 1 | E11: D | F11: 0 | G11: 100 | H11: 30 | I11: 100 | J11: =ROUND(Weights!$B$4*G11+Weights!$B$5*H11+Weights!$B$6*I11,0) -> 76 | K11: =IF(J11>=75,"Lower-processed",IF(J11>=45,"Moderately processed","Higher-processed")) -> Lower-processed | M11: Whole but high sugar
A12: 11 | B12: Pure maple syrup | C12: Sweetener | D12: 1 | E12: D | F12: 0 | G12: 100 | H12: 30 | I12: 100 | J12: =ROUND(Weights!$B$4*G12+Weights!$B$5*H12+Weights!$B$6*I12,0) -> 76 | K12: =IF(J12>=75,"Lower-processed",IF(J12>=45,"Moderately processed","Higher-processed")) -> Lower-processed
A13: 12 | B13: Natural peanut butter (peanuts only) | C13: Spread | D13: 2 | E13: C | F13: 0 | G13: 80 | H13: 50 | I13: 100 | J13: =ROUND(Weights!$B$4*G13+Weights!$B$5*H13+Weights!$B$6*I13,0) -> 73 | K13: =IF(J13>=75,"Lower-processed",IF(J13>=45,"Moderately processed","Higher-processed")) -> Moderately processed
A14: 13 | B14: Butter | C14: Dairy fat | D14: 3 | E14: D | F14: 0 | G14: 55 | H14: 30 | I14: 100 | J14: =ROUND(Weights!$B$4*G14+Weights!$B$5*H14+Weights!$B$6*I14,0) -> 53 | K14: =IF(J14>=75,"Lower-processed",IF(J14>=45,"Moderately processed","Higher-processed")) -> Moderately processed | M14: Sat fat dings nutrition
A15: 14 | B15: Cheddar cheese | C15: Dairy | D15: 3 | E15: D | F15: 0 | G15: 55 | H15: 30 | I15: 100 | J15: =ROUND(Weights!$B$4*G15+Weights!$B$5*H15+Weights!$B$6*I15,0) -> 53 | K15: =IF(J15>=75,"Lower-processed",IF(J15>=45,"Moderately processed","Higher-processed")) -> Moderately processed | M15: EDGE: nutrient-dense; compare vs sugary cereal
A16: 15 | B16: Canned chickpeas | C16: Legume | D16: 3 | E16: A | F16: 0 | G16: 55 | H16: 90 | I16: 100 | J16: =ROUND(Weights!$B$4*G16+Weights!$B$5*H16+Weights!$B$6*I16,0) -> 74 | K16: =IF(J16>=75,"Lower-processed",IF(J16>=45,"Moderately processed","Higher-processed")) -> Moderately processed
A17: 16 | B17: Hummus | C17: Spread | D17: 3 | E17: B | F17: 1 (low) | G17: 55 | H17: 70 | I17: 100 | J17: =ROUND(Weights!$B$4*G17+Weights!$B$5*H17+Weights!$B$6*I17,0) -> 67 | K17: =IF(J17>=75,"Lower-processed",IF(J17>=45,"Moderately processed","Higher-processed")) -> Moderately processed
A18: 17 | B18: Tofu | C18: Protein | D18: 3 | E18: B | F18: 0 | G18: 55 | H18: 70 | I18: 100 | J18: =ROUND(Weights!$B$4*G18+Weights!$B$5*H18+Weights!$B$6*I18,0) -> 67 | K18: =IF(J18>=75,"Lower-processed",IF(J18>=45,"Moderately processed","Higher-processed")) -> Moderately processed
A19: 18 | B19: Sourdough bread (artisan) | C19: Bakery | D19: 3 | E19: C | F19: 0 | G19: 55 | H19: 50 | I19: 100 | J19: =ROUND(Weights!$B$4*G19+Weights!$B$5*H19+Weights!$B$6*I19,0) -> 60 | K19: =IF(J19>=75,"Lower-processed",IF(J19>=45,"Moderately processed","Higher-processed")) -> Moderately processed
A20: 19 | B20: Salted roasted peanuts | C20: Nuts | D20: 3 | E20: B | F20: 1 (low) | G20: 55 | H20: 70 | I20: 100 | J20: =ROUND(Weights!$B$4*G20+Weights!$B$5*H20+Weights!$B$6*I20,0) -> 67 | K20: =IF(J20>=75,"Lower-processed",IF(J20>=45,"Moderately processed","Higher-processed")) -> Moderately processed
A21: 20 | B21: Dark chocolate 85% | C21: Confectionery | D21: 3 | E21: D | F21: 1 (low) | G21: 55 | H21: 30 | I21: 100 | J21: =ROUND(Weights!$B$4*G21+Weights!$B$5*H21+Weights!$B$6*I21,0) -> 53 | K21: =IF(J21>=75,"Lower-processed",IF(J21>=45,"Moderately processed","Higher-processed")) -> Moderately processed
A22: 21 | B22: Potato chips (plain salted) | C22: Snack | D22: 3 | E22: D | F22: 0 | G22: 55 | H22: 30 | I22: 100 | J22: =ROUND(Weights!$B$4*G22+Weights!$B$5*H22+Weights!$B$6*I22,0) -> 53 | K22: =IF(J22>=75,"Lower-processed",IF(J22>=45,"Moderately processed","Higher-processed")) -> Moderately processed
A23: 22 | B23: Ketchup | C23: Condiment | D23: 4 | E23: D | F23: 1 (low) | G23: 20 | H23: 30 | I23: 100 | J23: =ROUND(Weights!$B$4*G23+Weights!$B$5*H23+Weights!$B$6*I23,0) -> 36 | K23: =IF(J23>=75,"Lower-processed",IF(J23>=45,"Moderately processed","Higher-processed")) -> Higher-processed
A24: 23 | B24: Mustard | C24: Condiment | D24: 3 | E24: B | F24: 0 | G24: 55 | H24: 70 | I24: 100 | J24: =ROUND(Weights!$B$4*G24+Weights!$B$5*H24+Weights!$B$6*I24,0) -> 67 | K24: =IF(J24>=75,"Lower-processed",IF(J24>=45,"Moderately processed","Higher-processed")) -> Moderately processed
A25: 24 | B25: Kombucha | C25: Beverage | D25: 3 | E25: B | F25: 0 | G25: 55 | H25: 70 | I25: 100 | J25: =ROUND(Weights!$B$4*G25+Weights!$B$5*H25+Weights!$B$6*I25,0) -> 67 | K25: =IF(J25>=75,"Lower-processed",IF(J25>=45,"Moderately processed","Higher-processed")) -> Moderately processed
A26: 25 | B26: 100% orange juice | C26: Beverage | D26: 1 | E26: C | F26: 0 | G26: 100 | H26: 50 | I26: 100 | J26: =ROUND(Weights!$B$4*G26+Weights!$B$5*H26+Weights!$B$6*I26,0) -> 83 | K26: =IF(J26>=75,"Lower-processed",IF(J26>=45,"Moderately processed","Higher-processed")) -> Lower-processed | M26: Whole but sugar-heavy
A27: 26 | B27: Oat milk (fortified) | C27: Beverage | D27: 4 | E27: B | F27: 2 (low, low) | G27: 20 | H27: 70 | I27: 100 | J27: =ROUND(Weights!$B$4*G27+Weights!$B$5*H27+Weights!$B$6*I27,0) -> 50 | K27: =IF(J27>=75,"Lower-processed",IF(J27>=45,"Moderately processed","Higher-processed")) -> Moderately processed
A28: 27 | B28: Diet cola (sweeteners) | C28: Beverage | D28: 4 | E28: C | F28: 4 (moderate, moderate, moderate, low) | G28: 20 | H28: 50 | I28: 88 | J28: =ROUND(Weights!$B$4*G28+Weights!$B$5*H28+Weights!$B$6*I28,0) -> 41 | K28: =IF(J28>=75,"Lower-processed",IF(J28>=45,"Moderately processed","Higher-processed")) -> Higher-processed | M28: EDGE: OK nutrition but NOVA4 + additives → should score LOW (anti-Yuka)
A29: 28 | B29: Regular cola | C29: Beverage | D29: 4 | E29: E | F29: 2 (low, low) | G29: 20 | H29: 12 | I29: 100 | J29: =ROUND(Weights!$B$4*G29+Weights!$B$5*H29+Weights!$B$6*I29,0) -> 29 | K29: =IF(J29>=75,"Lower-processed",IF(J29>=45,"Moderately processed","Higher-processed")) -> Higher-processed
A30: 29 | B30: Energy drink | C30: Beverage | D30: 4 | E30: E | F30: 3 (moderate, moderate, low) | G30: 20 | H30: 12 | I30: 91 | J30: =ROUND(Weights!$B$4*G30+Weights!$B$5*H30+Weights!$B$6*I30,0) -> 28 | K30: =IF(J30>=75,"Lower-processed",IF(J30>=45,"Moderately processed","Higher-processed")) -> Higher-processed
A31: 30 | B31: Sports drink | C31: Beverage | D31: 4 | E31: D | F31: 2 (moderate, low) | G31: 20 | H31: 30 | I31: 94 | J31: =ROUND(Weights!$B$4*G31+Weights!$B$5*H31+Weights!$B$6*I31,0) -> 35 | K31: =IF(J31>=75,"Lower-processed",IF(J31>=45,"Moderately processed","Higher-processed")) -> Higher-processed
A32: 31 | B32: Multigrain Cheerios (fortified) | C32: Cereal | D32: 4 | E32: B | F32: 1 (low) | G32: 20 | H32: 70 | I32: 100 | J32: =ROUND(Weights!$B$4*G32+Weights!$B$5*H32+Weights!$B$6*I32,0) -> 50 | K32: =IF(J32>=75,"Lower-processed",IF(J32>=45,"Moderately processed","Higher-processed")) -> Moderately processed | M32: EDGE: compare vs Froot Loops
A33: 32 | B33: Froot Loops (sugary cereal) | C33: Cereal | D33: 4 | E33: E | F33: 3 (higher, moderate, moderate) | G33: 20 | H33: 12 | I33: 76 | J33: =ROUND(Weights!$B$4*G33+Weights!$B$5*H33+Weights!$B$6*I33,0) -> 26 | K33: =IF(J33>=75,"Lower-processed",IF(J33>=45,"Moderately processed","Higher-processed")) -> Higher-processed | M33: Colours + BHT
A34: 33 | B34: Granola (sweetened) | C34: Cereal | D34: 4 | E34: C | F34: 0 | G34: 20 | H34: 50 | I34: 100 | J34: =ROUND(Weights!$B$4*G34+Weights!$B$5*H34+Weights!$B$6*I34,0) -> 43 | K34: =IF(J34>=75,"Lower-processed",IF(J34>=45,"Moderately processed","Higher-processed")) -> Higher-processed
A35: 34 | B35: Instant ramen noodles | C35: Meal | D35: 4 | E35: E | F35: 3 (moderate, moderate, low) | G35: 20 | H35: 12 | I35: 91 | J35: =ROUND(Weights!$B$4*G35+Weights!$B$5*H35+Weights!$B$6*I35,0) -> 28 | K35: =IF(J35>=75,"Lower-processed",IF(J35>=45,"Moderately processed","Higher-processed")) -> Higher-processed
A36: 35 | B36: Canned condensed soup | C36: Meal | D36: 4 | E36: D | F36: 2 (moderate, low) | G36: 20 | H36: 30 | I36: 94 | J36: =ROUND(Weights!$B$4*G36+Weights!$B$5*H36+Weights!$B$6*I36,0) -> 35 | K36: =IF(J36>=75,"Lower-processed",IF(J36>=45,"Moderately processed","Higher-processed")) -> Higher-processed
A37: 36 | B37: Frozen pizza | C37: Meal | D37: 4 | E37: D | F37: 3 (moderate, low, low) | G37: 20 | H37: 30 | I37: 94 | J37: =ROUND(Weights!$B$4*G37+Weights!$B$5*H37+Weights!$B$6*I37,0) -> 35 | K37: =IF(J37>=75,"Lower-processed",IF(J37>=45,"Moderately processed","Higher-processed")) -> Higher-processed
A38: 37 | B38: Milk chocolate bar | C38: Confectionery | D38: 4 | E38: E | F38: 1 (low) | G38: 20 | H38: 12 | I38: 100 | J38: =ROUND(Weights!$B$4*G38+Weights!$B$5*H38+Weights!$B$6*I38,0) -> 29 | K38: =IF(J38>=75,"Lower-processed",IF(J38>=45,"Moderately processed","Higher-processed")) -> Higher-processed | M38: Emulsifier = low concern
A39: 38 | B39: Flavoured fruit yogurt | C39: Dairy | D39: 4 | E39: C | F39: 2 (low, moderate) | G39: 20 | H39: 50 | I39: 94 | J39: =ROUND(Weights!$B$4*G39+Weights!$B$5*H39+Weights!$B$6*I39,0) -> 42 | K39: =IF(J39>=75,"Lower-processed",IF(J39>=45,"Moderately processed","Higher-processed")) -> Higher-processed
A40: 39 | B40: Protein bar | C40: Snack | D40: 4 | E40: C | F40: 2 (moderate, low) | G40: 20 | H40: 50 | I40: 94 | J40: =ROUND(Weights!$B$4*G40+Weights!$B$5*H40+Weights!$B$6*I40,0) -> 42 | K40: =IF(J40>=75,"Lower-processed",IF(J40>=45,"Moderately processed","Higher-processed")) -> Higher-processed
...
